Workbook

Sheet Top 100 Jobs
A1: Rank | B1: Job | C1: Group | D1: What it covers | E1: Typical time (min) | F1: Member has the part? | G1: Licensed-trade note | H1: Research angles listing it (of 9) | I1: Mentions | J1: Score | K1: Tier | L1: Search keywords | M1: In today's prototype | N1: Confidence | O1: Note
A2: =RANK(J2,$J$2:$J$101)+COUNTIF($J$2:J2,J2)-1 -> 1 | B2: Patch a hole in drywall | C2: Walls, Paint & Tile | D2: Repair small and medium holes (up to about 6 inches) and dents in drywall with a patch kit and setting-type compound, ready for paint; does not include large sections, texture matching across a whole wall or painting the full room. | E2: 90 | F2: Either | G2: Pre-1978 homes: lead-safe check before sanding painted surfaces | H2: =SUMPRODUCT(--(COUNTIFS(Evidence!$A$2:$A$680,B2,Evidence!$B$2:$B$680,{"A","B","C","D","E","F","G","H","I"})>0)) -> 9 | I2: =COUNTIF(Evidence!$A$2:$A$680,B2) -> 17 | J2: =H2*'Method & Notes'!$B$4+MIN(I2,'Method & Notes'!$B$6)*'Method & Notes'!$B$5 -> 98 | K2: =IF(J2>='Method & Notes'!$B$7,"A - Core",IF(J2>='Method & Notes'!$B$8,"B - Common","C - Frequent")) -> A - Core | L2: drywall patch, hole in wall, wall repair, drywall repair, doorknob hole, nail holes, sheetrock, spackle | M2: New | N2: =IF(H2>=6,"High",IF(H2>=3,"Medium","Low")) -> High
A3: =RANK(J3,$J$2:$J$101)+COUNTIF($J$2:J3,J3)-1 -> 2 | B3: Replace a ceiling fan | C3: Lighting & Electrical Swaps | D3: Replace an existing ceiling fan (or fan-light) with a like-for-like fan you provide on an existing fan-rated box, ceiling about 9 ft or lower, including assembly and balancing; light-to-fan conversions, new fan locations and new wiring are not included. | E3: 120 | F3: Member supplies part | G3: Swap on existing fan-rated box and wiring only; a light-to-fan conversion or new fan location is new wiring and box work | H3: =SUMPRODUCT(--(COUNTIFS(Evidence!$A$2:$A$680,B3,Evidence!$B$2:$B$680,{"A","B","C","D","E","F","G","H","I"})>0)) -> 9 | I3: =COUNTIF(Evidence!$A$2:$A$680,B3) -> 18 | J3: =H3*'Method & Notes'!$B$4+MIN(I3,'Method & Notes'!$B$6)*'Method & Notes'!$B$5 -> 98 | K3: =IF(J3>='Method & Notes'!$B$7,"A - Core",IF(J3>='Method & Notes'!$B$8,"B - Common","C - Frequent")) -> A - Core | L3: replace ceiling fan, install ceiling fan, swap fan, fan install, ceiling fan swap, new fan, fan light kit | M3: Replace a ceiling or bath fan | N3: =IF(H3>=6,"High",IF(H3>=3,"Medium","Low")) -> High
A4: =RANK(J4,$J$2:$J$101)+COUNTIF($J$2:J4,J4)-1 -> 3 | B4: Replace a light fixture | C4: Lighting & Electrical Swaps | D4: Swap an existing ceiling or wall light for a like-for-like fixture you provide, on the existing rated box and wiring with ceilings about 9 ft or lower; no new fixture locations, new boxes or new wiring. | E4: 60 | F4: Member supplies part | G4: Like-for-like swap only; no new wiring or new box; stop on aluminum, cloth-covered or damaged wiring or a loose or unrated box | H4: =SUMPRODUCT(--(COUNTIFS(Evidence!$A$2:$A$680,B4,Evidence!$B$2:$B$680,{"A","B","C","D","E","F","G","H","I"})>0)) -> 8 | I4: =COUNTIF(Evidence!$A$2:$A$680,B4) -> 16 | J4: =H4*'Method & Notes'!$B$4+MIN(I4,'Method & Notes'!$B$6)*'Method & Notes'!$B$5 -> 88 | K4: =IF(J4>='Method & Notes'!$B$7,"A - Core",IF(J4>='Method & Notes'!$B$8,"B - Common","C - Frequent")) -> A - Core | L4: replace light fixture, install light, swap light, ceiling light, vanity light, flush mount, light install, change light fixture | M4: Replace a light fixture | N4: =IF(H4>=6,"High",IF(H4>=3,"Medium","Low")) -> High
A5: =RANK(J5,$J$2:$J$101)+COUNTIF($J$2:J5,J5)-1 -> 4 | B5: Fix a running toilet | C5: Plumbing | D5: Stop a toilet that runs, keeps refilling or flushes weakly by swapping the flapper or fill valve, adjusting the chain or float, or clearing the rim jets; does not include replacing the toilet or fixing a cracked tank. | E5: 45 | F5: Either | G5: Internal parts only; no supply or drain changes | H5: =SUMPRODUCT(--(COUNTIFS(Evidence!$A$2:$A$680,B5,Evidence!$B$2:$B$680,{"A","B","C","D","E","F","G","H","I"})>0)) -> 8 | I5: =COUNTIF(Evidence!$A$2:$A$680,B5) -> 18 | J5: =H5*'Method & Notes'!$B$4+MIN(I5,'Method & Notes'!$B$6)*'Method & Notes'!$B$5 -> 88 | K5: =IF(J5>='Method & Notes'!$B$7,"A - Core",IF(J5>='Method & Notes'!$B$8,"B - Common","C - Frequent")) -> A - Core | L5: running toilet, toilet keeps running, flapper, fill valve, toilet runs, phantom flush, toilet chain, weak flush, slow refill | M5: Running toilet | N5: =IF(H5>=6,"High",IF(H5>=3,"Medium","Low")) -> High
A6: =RANK(J6,$J$2:$J$101)+COUNTIF($J$2:J6,J6)-1 -> 5 | B6: Re-caulk a tub, shower or sink | C6: Walls, Paint & Tile | D6: Remove failed caulk and apply a fresh bead around a tub, shower or sink; cure time is on the member and tile or grout replacement is not included. | E6: 75 | F6: Either | G6: None | H6: =SUMPRODUCT(--(COUNTIFS(Evidence!$A$2:$A$680,B6,Evidence!$B$2:$B$680,{"A","B","C","D","E","F","G","H","I"})>0)) -> 8 | I6: =COUNTIF(Evidence!$A$2:$A$680,B6) -> 13 | J6: =H6*'Method & Notes'!$B$4+MIN(I6,'Method & Notes'!$B$6)*'Method & Notes'!$B$5 -> 88 | K6: =IF(J6>='Method & Notes'!$B$7,"A - Core",IF(J6>='Method & Notes'!$B$8,"B - Common","C - Frequent")) -> A - Core | L6: caulk tub, recaulk shower, bathroom caulk, seal sink, caulking, silicone, moldy caulk, reseal tub | M6: New | N6: =IF(H6>=6,"High",IF(H6>=3,"Medium","Low")) -> High
A7: =RANK(J7,$J$2:$J$101)+COUNTIF($J$2:J7,J7)-1 -> 6 | B7: Install a smart thermostat | C7: Lighting & Electrical Swaps | D7: Swap an existing low-voltage thermostat for a smart or programmable one you provide using the existing wires (including a C-wire if already present) and set it up in the app; no new C-wire run, baseboard line-voltage units or HVAC work. | E7: 60 | F7: Member supplies part | G7: Existing low-voltage wires only; no new wiring or C-wire run; baseboard or multistage heat-pump setups go to an HVAC tech | H7: =SUMPRODUCT(--(COUNTIFS(Evidence!$A$2:$A$680,B7,Evidence!$B$2:$B$680,{"A","B","C","D","E","F","G","H","I"})>0)) -> 8 | I7: =COUNTIF(Evidence!$A$2:$A$680,B7) -> 16 | J7: =H7*'Method & Notes'!$B$4+MIN(I7,'Method & Notes'!$B$6)*'Method & Notes'!$B$5 -> 88 | K7: =IF(J7>='Method & Notes'!$B$7,"A - Core",IF(J7>='Method & Notes'!$B$8,"B - Common","C - Frequent")) -> A - Core | L7: smart thermostat, Nest, ecobee, thermostat install, replace thermostat, programmable thermostat, Wi-Fi thermostat | M7: Install a smart thermostat | N7: =IF(H7>=6,"High",IF(H7>=3,"Medium","Low")) -> High
A8: =RANK(J8,$J$2:$J$101)+COUNTIF($J$2:J8,J8)-1 -> 7 | B8: Fix a door that sticks, rubs, squeaks or will not latch | C8: Doors & Locks | D8: Adjust hinges, strike plate or door edge so an interior or exterior door opens, closes and latches smoothly and stops squeaking; does not include hanging a new door. | E8: 45 | F8: No part needed | G8: None | H8: =SUMPRODUCT(--(COUNTIFS(Evidence!$A$2:$A$680,B8,Evidence!$B$2:$B$680,{"A","B","C","D","E","F","G","H","I"})>0)) -> 7 | I8: =COUNTIF(Evidence!$A$2:$A$680,B8) -> 15 | J8: =H8*'Method & Notes'!$B$4+MIN(I8,'Method & Notes'!$B$6)*'Method & Notes'!$B$5 -> 78 | K8: =IF(J8>='Method & Notes'!$B$7,"A - Core",IF(J8>='Method & Notes'!$B$8,"B - Common","C - Frequent")) -> A - Core | L8: sticking door, door rubs, door won't close, door won't latch, strike plate, misaligned door, squeaky door, door hinge, sagging door, door adjust | M8: New | N8: =IF(H8>=6,"High",IF(H8>=3,"Medium","Low")) -> High
A9: =RANK(J9,$J$2:$J$101)+COUNTIF($J$2:J9,J9)-1 -> 8 | B9: Replace a garbage disposal | C9: Kitchen & Appliances | D9: Swap a worn-out disposal for a like-for-like unit you provide where the sink drain, switch and power (plug-in cord or existing hardwired lead) already exist; no first-time installs, drain changes or new outlets. | E9: 120 | F9: Member supplies part | G9: Like-for-like swap only; no drain rerouting or new electrical | H9: =SUMPRODUCT(--(COUNTIFS(Evidence!$A$2:$A$680,B9,Evidence!$B$2:$B$680,{"A","B","C","D","E","F","G","H","I"})>0)) -> 7 | I9: =COUNTIF(Evidence!$A$2:$A$680,B9) -> 14 | J9: =H9*'Method & Notes'!$B$4+MIN(I9,'Method & Notes'!$B$6)*'Method & Notes'!$B$5 -> 78 | K9: =IF(J9>='Method & Notes'!$B$7,"A - Core",IF(J9>='Method & Notes'!$B$8,"B - Common","C - Frequent")) -> A - Core | L9: replace garbage disposal, install disposal, disposer swap, kitchen disposal, new disposal, sink grinder | M9: New | N9: =IF(H9>=6,"High",IF(H9>=3,"Medium","Low")) -> High
A10: =RANK(J10,$J$2:$J$101)+COUNTIF($J$2:J10,J10)-1 -> 9 | B10: Replace a faucet | C10: Plumbing | D10: Swap a kitchen or bathroom faucet for a like-for-like one you provide, same hole count and location, using the existing shutoff valves and supply lines (or new supply lines you provide); no moving or adding water or drain lines and no drilling stone sinks. | E10: 90 | F10: Member supplies part | G10: Like-for-like swap only; seized shutoffs, corroded or soldered supply lines or moved lines go to a plumber | H10: =SUMPRODUCT(--(COUNTIFS(Evidence!$A$2:$A$680,B10,Evidence!$B$2:$B$680,{"A","B","C","D","E","F","G","H","I"})>0)) -> 7 | I10: =COUNTIF(Evidence!$A$2:$A$680,B10) -> 13 | J10: =H10*'Method & Notes'!$B$4+MIN(I10,'Method & Notes'!$B$6)*'Method & Notes'!$B$5 -> 78 | K10: =IF(J10>='Method & Notes'!$B$7,"A - Core",IF(J10>='Method & Notes'!$B$8,"B - Common","C - Frequent")) -> A - Core | L10: replace faucet, install faucet, new faucet, kitchen faucet, bathroom faucet, swap tap, faucet install, sink faucet | M10: Replace a faucet | N10: =IF(H10>=6,"High",IF(H10>=3,"Medium","Low")) -> High
A11: =RANK(J11,$J$2:$J$101)+COUNTIF($J$2:J11,J11)-1 -> 10 | B11: Fix a leaky or low-flow faucet | C11: Plumbing | D11: Stop a drip or leak at a kitchen or bathroom faucet by swapping the cartridge, washer or O-ring you provide, or restore flow by cleaning or replacing a clogged aerator; does not include replacing the faucet or fixing leaking supply lines or valves in the wall. | E11: 60 | F11: Either | G11: Fixture-side repair only; corroded valves or in-wall leaks go to a plumber | H11: =SUMPRODUCT(--(COUNTIFS(Evidence!$A$2:$A$680,B11,Evidence!$B$2:$B$680,{"A","B","C","D","E","F","G","H","I"})>0)) -> 7 | I11: =COUNTIF(Evidence!$A$2:$A$680,B11) -> 16 | J11: =H11*'Method & Notes'!$B$4+MIN(I11,'Method & Notes'!$B$6)*'Method & Notes'!$B$5 -> 78 | K11: =IF(J11>='Method & Notes'!$B$7,"A - Core",IF(J11>='Method & Notes'!$B$8,"B - Common","C - Frequent")) -> A - Core | L11: leaky faucet, dripping faucet, faucet drip, faucet leak, cartridge, washer, O-ring, tap leak, faucet aerator, low water pressure faucet, clogged aerator | M11: New | N11: =IF(H11>=6,"High",IF(H11>=3,"Medium","Low")) -> High
A12: =RANK(J12,$J$2:$J$101)+COUNTIF($J$2:J12,J12)-1 -> 11 | B12: Replace an electrical outlet | C12: Lighting & Electrical Swaps | D12: Swap a worn, loose or dead receptacle for a same-type outlet on existing wiring (add 15 minutes per extra outlet); does not include adding new outlets or circuits, or putting a grounded outlet where there is no ground wire. | E12: 30 | F12: Member supplies part | G12: Like-for-like swap only; no new outlets, circuits or wiring; stop on aluminum wiring, no ground, or scorched or hot outlets (electrician) | H12: =SUMPRODUCT(--(COUNTIFS(Evidence!$A$2:$A$680,B12,Evidence!$B$2:$B$680,{"A","B","C","D","E","F","G","H","I"})>0)) -> 7 | I12: =COUNTIF(Evidence!$A$2:$A$680,B12) -> 12 | J12: =H12*'Method & Notes'!$B$4+MIN(I12,'Method & Notes'!$B$6)*'Method & Notes'!$B$5 -> 78 | K12: =IF(J12>='Method & Notes'!$B$7,"A - Core",IF(J12>='Method & Notes'!$B$8,"B - Common","C - Frequent")) -> A - Core | L12: replace outlet, receptacle, dead outlet, loose outlet, plug socket, change outlet, outlet swap, tamper-resistant outlet | M12: New | N12: =IF(H12>=6,"High",IF(H12>=3,"Medium","Low")) -> High
A13: =RANK(J13,$J$2:$J$101)+COUNTIF($J$2:J13,J13)-1 -> 12 | B13: Touch up paint on walls or trim | C13: Walls, Paint & Tile | D13: Spot-paint patches, scuffs or a single small wall section or trim run with matching paint you provide; full rooms are not included. | E13: 60 | F13: Member supplies part | G13: Pre-1978 homes: lead-safe check before sanding or scraping | H13: =SUMPRODUCT(--(COUNTIFS(Evidence!$A$2:$A$680,B13,Evidence!$B$2:$B$680,{"A","B","C","D","E","F","G","H","I"})>0)) -> 7 | I13: =COUNTIF(Evidence!$A$2:$A$680,B13) -> 9 | J13: =H13*'Method & Notes'!$B$4+MIN(I13,'Method & Notes'!$B$6)*'Method & Notes'!$B$5 -> 78 | K13: =IF(J13>='Method & Notes'!$B$7,"A - Core",IF(J13>='Method & Notes'!$B$8,"B - Common","C - Frequent")) -> A - Core | L13: touch up paint, paint patch, wall touch-up, scuffs, trim paint, spot paint, paint after repair, small paint job | M13: New | N13: =IF(H13>=6,"High",IF(H13>=3,"Medium","Low")) -> High
... A99: =RANK(J99,$J$2:$J$101)+COUNTIF($J$2:J99,J99)-1 -> 98 | B99: Repair or restring window blinds | C99: Windows & Blinds | D99: Repair or restring corded blinds and shades, or replace broken cords, wands or brackets with parts you provide; custom blinds that must be remade are not included. | E99: 45 | F99: Either | G99: None | H99: =SUMPRODUCT(--(COUNTIFS(Evidence!$A$2:$A$680,B99,Evidence!$B$2:$B$680,{"A","B","C","D","E","F","G","H","I"})>0)) -> 1 | I99: =COUNTIF(Evidence!$A$2:$A$680,B99) -> 1 | J99: =H99*'Method & Notes'!$B$4+MIN(I99,'Method & Notes'!$B$6)*'Method & Notes'!$B$5 -> 11 | K99: =IF(J99>='Method & Notes'!$B$7,"A - Core",IF(J99>='Method & Notes'!$B$8,"B - Common","C - Frequent")) -> C - Frequent | L99: broken blinds, restring blinds, blind cord, blind wand, bent slats, blind bracket, repair shades | M99: Repair or re-string blinds | N99: =IF(H99>=6,"High",IF(H99>=3,"Medium","Low")) -> Low
A100: =RANK(J100,$J$2:$J$101)+COUNTIF($J$2:J100,J100)-1 -> 99 | B100: Fix a door lock that sticks or will not turn | C100: Doors & Locks | D100: Clean and lubricate the cylinder, tighten the set screw, adjust the strike plate or latch, or swap in a matching cylinder. Does not include a key broken off in the lock, lockouts or re-keying a whole house. | E100: 45 | F100: Either | G100: None; lockouts and broken keys go to a locksmith | H100: =SUMPRODUCT(--(COUNTIFS(Evidence!$A$2:$A$680,B100,Evidence!$B$2:$B$680,{"A","B","C","D","E","F","G","H","I"})>0)) -> 0 | I100: =COUNTIF(Evidence!$A$2:$A$680,B100) -> 3 | J100: =H100*'Method & Notes'!$B$4+MIN(I100,'Method & Notes'!$B$6)*'Method & Notes'!$B$5 -> 3 | K100: =IF(J100>='Method & Notes'!$B$7,"A - Core",IF(J100>='Method & Notes'!$B$8,"B - Common","C - Frequent")) -> C - Frequent | L100: lock sticks, key will not turn, stuck deadbolt, jammed lock, door lock issue, stiff lock, strike plate, lock repair | M100: New | N100: =IF(H100>=6,"High",IF(H100>=3,"Medium","Low")) -> Low | O100: Stakeholder example (Slack); thin independent evidence
A101: =RANK(J101,$J$2:$J$101)+COUNTIF($J$2:J101,J101)-1 -> 100 | B101: Diagnose an appliance that is not working | C101: Kitchen & Appliances | D101: Check power, settings, filters, hoses, door seals and simple parts on a refrigerator, washer, dryer, dishwasher, oven or microwave and tell the member what is wrong. Does not include repairs that need an appliance technician, sealed-system or control-board work, or any gas work. | E101: 60 | F101: No part needed (diagnosis) | G101: No gas work; sealed-system, board or gas repairs are referred out | H101: =SUMPRODUCT(--(COUNTIFS(Evidence!$A$2:$A$680,B101,Evidence!$B$2:$B$680,{"A","B","C","D","E","F","G","H","I"})>0)) -> 0 | I101: =COUNTIF(Evidence!$A$2:$A$680,B101) -> 3 | J101: =H101*'Method & Notes'!$B$4+MIN(I101,'Method & Notes'!$B$6)*'Method & Notes'!$B$5 -> 3 | K101: =IF(J101>='Method & Notes'!$B$7,"A - Core",IF(J101>='Method & Notes'!$B$8,"B - Common","C - Frequent")) -> C - Frequent | L101: appliance not working, fridge not cooling, washer will not drain, dryer will not heat, oven will not heat, dishwasher not draining, diagnose appliance, appliance diagnostic | M101: New | N101: =IF(H101>=6,"High",IF(H101>=3,"Medium","Low")) -> Low | O101: Stakeholder example (Slack); thin independent evidence
B103: Row count check | C103: =COUNTA(B2:B101) -> 100
B104: Typical time, average (min) | C104: =AVERAGE(E2:E101) -> 71.25
B105: Confidence = High with 6 or more research angles, Medium with 3 to 5, otherwise Low.
B106: Rank and score are formulas driven by the Evidence sheet and the inputs on "Method & Notes". Rows are listed best-supported first.

Sheet Groups
A1: Group | B1: Jobs | C1: Share of jobs | D1: Average typical time (min) | E1: Average score | F1: Core (A) jobs
A2: Plumbing | B2: =COUNTIF('Top 100 Jobs'!$C$2:$C$101,A2) -> 14 | C2: =B2/$B$12 -> 0.14 | D2: =AVERAGEIF('Top 100 Jobs'!$C$2:$C$101,A2,'Top 100 Jobs'!$E$2:$E$101) -> 61.071429 | E2: =AVERAGEIF('Top 100 Jobs'!$C$2:$C$101,A2,'Top 100 Jobs'!$J$2:$J$101) -> 53.214286 | F2: =COUNTIFS('Top 100 Jobs'!$C$2:$C$101,A2,'Top 100 Jobs'!$K$2:$K$101,"A - Core") -> 4
A3: Doors & Locks | B3: =COUNTIF('Top 100 Jobs'!$C$2:$C$101,A3) -> 11 | C3: =B3/$B$12 -> 0.11 | D3: =AVERAGEIF('Top 100 Jobs'!$C$2:$C$101,A3,'Top 100 Jobs'!$E$2:$E$101) -> 64.090909 | E3: =AVERAGEIF('Top 100 Jobs'!$C$2:$C$101,A3,'Top 100 Jobs'!$J$2:$J$101) -> 45.454545 | F3: =COUNTIFS('Top 100 Jobs'!$C$2:$C$101,A3,'Top 100 Jobs'!$K$2:$K$101,"A - Core") -> 3
A4: Walls, Paint & Tile | B4: =COUNTIF('Top 100 Jobs'!$C$2:$C$101,A4) -> 9 | C4: =B4/$B$12 -> 0.09 | D4: =AVERAGEIF('Top 100 Jobs'!$C$2:$C$101,A4,'Top 100 Jobs'!$E$2:$E$101) -> 95 | E4: =AVERAGEIF('Top 100 Jobs'!$C$2:$C$101,A4,'Top 100 Jobs'!$J$2:$J$101) -> 52.666667 | F4: =COUNTIFS('Top 100 Jobs'!$C$2:$C$101,A4,'Top 100 Jobs'!$K$2:$K$101,"A - Core") -> 3
A5: Mounting & Hanging | B5: =COUNTIF('Top 100 Jobs'!$C$2:$C$101,A5) -> 8 | C5: =B5/$B$12 -> 0.08 | D5: =AVERAGEIF('Top 100 Jobs'!$C$2:$C$101,A5,'Top 100 Jobs'!$E$2:$E$101) -> 69.375 | E5: =AVERAGEIF('Top 100 Jobs'!$C$2:$C$101,A5,'Top 100 Jobs'!$J$2:$J$101) -> 45.125 | F5: =COUNTIFS('Top 100 Jobs'!$C$2:$C$101,A5,'Top 100 Jobs'!$K$2:$K$101,"A - Core") -> 2
A6: Lighting & Electrical Swaps | B6: =COUNTIF('Top 100 Jobs'!$C$2:$C$101,A6) -> 14 | C6: =B6/$B$12 -> 0.14 | D6: =AVERAGEIF('Top 100 Jobs'!$C$2:$C$101,A6,'Top 100 Jobs'!$E$2:$E$101) -> 63.214286 | E6: =AVERAGEIF('Top 100 Jobs'!$C$2:$C$101,A6,'Top 100 Jobs'!$J$2:$J$101) -> 55.571429 | F6: =COUNTIFS('Top 100 Jobs'!$C$2:$C$101,A6,'Top 100 Jobs'!$K$2:$K$101,"A - Core") -> 4
A7: Kitchen & Appliances | B7: =COUNTIF('Top 100 Jobs'!$C$2:$C$101,A7) -> 13 | C7: =B7/$B$12 -> 0.13 | D7: =AVERAGEIF('Top 100 Jobs'!$C$2:$C$101,A7,'Top 100 Jobs'!$E$2:$E$101) -> 75 | E7: =AVERAGEIF('Top 100 Jobs'!$C$2:$C$101,A7,'Top 100 Jobs'!$J$2:$J$101) -> 33.384615 | F7: =COUNTIFS('Top 100 Jobs'!$C$2:$C$101,A7,'Top 100 Jobs'!$K$2:$K$101,"A - Core") -> 1
A8: Furniture & Assembly | B8: =COUNTIF('Top 100 Jobs'!$C$2:$C$101,A8) -> 7 | C8: =B8/$B$12 -> 0.07 | D8: =AVERAGEIF('Top 100 Jobs'!$C$2:$C$101,A8,'Top 100 Jobs'!$E$2:$E$101) -> 92.142857 | E8: =AVERAGEIF('Top 100 Jobs'!$C$2:$C$101,A8,'Top 100 Jobs'!$J$2:$J$101) -> 24.571429 | F8: =COUNTIFS('Top 100 Jobs'!$C$2:$C$101,A8,'Top 100 Jobs'!$K$2:$K$101,"A - Core") -> 1
A9: Windows & Blinds | B9: =COUNTIF('Top 100 Jobs'!$C$2:$C$101,A9) -> 7 | C9: =B9/$B$12 -> 0.07 | D9: =AVERAGEIF('Top 100 Jobs'!$C$2:$C$101,A9,'Top 100 Jobs'!$E$2:$E$101) -> 64.285714 | E9: =AVERAGEIF('Top 100 Jobs'!$C$2:$C$101,A9,'Top 100 Jobs'!$J$2:$J$101) -> 44.571429 | F9: =COUNTIFS('Top 100 Jobs'!$C$2:$C$101,A9,'Top 100 Jobs'!$K$2:$K$101,"A - Core") -> 0
A10: Home Care & Safety | B10: =COUNTIF('Top 100 Jobs'!$C$2:$C$101,A10) -> 9 | C10: =B10/$B$12 -> 0.09 | D10: =AVERAGEIF('Top 100 Jobs'!$C$2:$C$101,A10,'Top 100 Jobs'!$E$2:$E$101) -> 51.666667 | E10: =AVERAGEIF('Top 100 Jobs'!$C$2:$C$101,A10,'Top 100 Jobs'!$J$2:$J$101) -> 33.555556 | F10: =COUNTIFS('Top 100 Jobs'!$C$2:$C$101,A10,'Top 100 Jobs'!$K$2:$K$101,"A - Core") -> 0
A11: Outdoors & Other | B11: =COUNTIF('Top 100 Jobs'!$C$2:$C$101,A11) -> 8 | C11: =B11/$B$12 -> 0.08 | D11: =AVERAGEIF('Top 100 Jobs'!$C$2:$C$101,A11,'Top 100 Jobs'!$E$2:$E$101) -> 91.875 | E11: =AVERAGEIF('Top 100 Jobs'!$C$2:$C$101,A11,'Top 100 Jobs'!$J$2:$J$101) -> 32.75 | F11: =COUNTIFS('Top 100 Jobs'!$C$2:$C$101,A11,'Top 100 Jobs'!$K$2:$K$101,"A - Core") -> 0
A12: Total | B12: =SUM(B2:B11) -> 100 | C12: =SUM(C2:C11) -> 1 | F12: =SUM(F2:F11) -> 18
A14: Check: total equals 100 | B14: =IF(B12=100,"OK","CHECK") -> OK

Sheet Evidence
A1: Job | B1: Angle | C1: Angle name | D1: Source | E1: URL | F1: What the source shows
A2: Patch a hole in drywall | B2: A | C2: =IFERROR(INDEX('Method & Notes'!$B$24:$B$34,MATCH(B2,'Method & Notes'!$A$24:$A$34,0)),"") -> Marketplaces and booking platforms | D2: Thumbtack | E2: https://www.thumbtack.com/p/drywall-repair-cost | F2: dedicated drywall repair guide; dent and nail-hole fixes from $75 (snippet)
A3: Patch a hole in drywall | B3: A | C3: =IFERROR(INDEX('Method & Notes'!$B$24:$B$34,MATCH(B3,'Method & Notes'!$A$24:$A$34,0)),"") -> Marketplaces and booking platforms | D3: Angi | E3: https://www.angi.com/articles/what-are-common-handyman-prices.htm | F3: handyman price table lists drywall patch at $120-$350 (snippet)
A4: Patch a hole in drywall | B4: A | C4: =IFERROR(INDEX('Method & Notes'!$B$24:$B$34,MATCH(B4,'Method & Notes'!$A$24:$A$34,0)),"") -> Marketplaces and booking platforms | D4: Amenify | E4: https://www.amenify.com/blog/top-handyman-tasks-for-homeowners-in-us | F4: core services list names drywall repair with touch-up painting (snippet)
A5: Patch a hole in drywall | B5: B | C5: =IFERROR(INDEX('Method & Notes'!$B$24:$B$34,MATCH(B5,'Method & Notes'!$A$24:$A$34,0)),"") -> Handyman business guides | D5: Thimble | E5: https://www.thimble.com/blog/what-are-the-most-requested-handyman-services | F5: 2026 list from search + customer data: drywall install/repair listed 1st of 7 (snippet)
A6: Patch a hole in drywall | B6: B | C6: =IFERROR(INDEX('Method & Notes'!$B$24:$B$34,MATCH(B6,'Method & Notes'!$A$24:$A$34,0)),"") -> Handyman business guides | D6: Bob Vila | E6: https://www.bobvila.com/articles/handyman-services-list/ | F6: contractor quoted: drywall repair among most popular requests; one handyman ranks it #1 (snippet)
A7: Patch a hole in drywall | B7: C | C7: =IFERROR(INDEX('Method & Notes'!$B$24:$B$34,MATCH(B7,'Method & Notes'!$A$24:$A$34,0)),"") -> Warranty claims and inspections | D7: OnePoll deferred-repairs survey (InsightDIY) | E7: https://insightdiy.co.uk/news/us-homeowners-most-likely-to-put-off-painting-over-other-diy-tasks/10838.htm | F7: Fixing holes in walls: 40% of homeowners put it off, tied for 2nd (snippet)
A8: Patch a hole in drywall | B8: D | C8: =IFERROR(INDEX('Method & Notes'!$B$24:$B$34,MATCH(B8,'Method & Notes'!$A$24:$A$34,0)),"") -> DIY and how-to interest | D8: Family Handyman: 10 Most Popular Home Repairs for New Homeowners | E8: https://www.familyhandyman.com/list/most-popular-home-repairs-for-new-homeowners/ | F8: Drywall patching listed #7 of 10 most popular new-homeowner repairs (snippet)
A9: Patch a hole in drywall | B9: D | C9: =IFERROR(INDEX('Method & Notes'!$B$24:$B$34,MATCH(B9,'Method & Notes'!$A$24:$A$34,0)),"") -> DIY and how-to interest | D9: Lowe's Home Repair Workshops press release (Nov 2023) | E9: https://corporate.lowes.com/newsroom/press-releases/lowes-debuts-new-way-teach-millennials-how-make-basic-home-repairs-helping-homeowners-build-diy-confidence-and-save-costs-11-10-23 | F9: Workshop topic: patching and repairing drywall (snippet)
A10: Patch a hole in drywall | B10: E | C10: =IFERROR(INDEX('Method & Notes'!$B$24:$B$34,MATCH(B10,'Method & Notes'!$A$24:$A$34,0)),"") -> Rental and property maintenance requests | D10: Rental Real Estate handyman blog | E10: https://rentalrealestate.com/blog/essential-role-of-handyman-in-rental-property-maintenance/ | F10: Patching drywall named among most common rental handyman repairs (snippet)
A11: Patch a hole in drywall | B11: F | C11: =IFERROR(INDEX('Method & Notes'!$B$24:$B$34,MATCH(B11,'Method & Notes'!$A$24:$A$34,0)),"") -> Memberships, concierge and retailer services | D11: Mr. Handyman, Collin County TX (Community Impact) | E11: https://communityimpact.com/mckinney/business/mr-handyman-of-midwest-collin-county-finds-success-in-full-service-residential-commercial-property-repairs-maintenance/ | F11: Top 3 most-requested at one franchise: doors, drywall, honey-do (single location) (snippet)
A12: Patch a hole in drywall | B12: G | C12: =IFERROR(INDEX('Method & Notes'!$B$24:$B$34,MATCH(B12,'Method & Notes'!$A$24:$A$34,0)),"") -> Time, cost and scope guides | D12: TaskRabbit | E12: https://www.taskrabbit.com/cost-guides/drywall-repair | F12: Dedicated drywall repair cost guide; $38/hr average in the U.S. (snippet)
A13: Patch a hole in drywall | B13: G | C13: =IFERROR(INDEX('Method & Notes'!$B$24:$B$34,MATCH(B13,'Method & Notes'!$A$24:$A$34,0)),"") -> Time, cost and scope guides | D13: Fixr | E13: https://www.fixr.com/costs/repair-drywall | F13: Dedicated 'repair drywall' cost page, updated January 31, 2025 (snippet)
... A676: Fix a door lock that sticks or will not turn | B676: J | C676: =IFERROR(INDEX('Method & Notes'!$B$24:$B$34,MATCH(B676,'Method & Notes'!$A$24:$A$34,0)),"") -> Extra web searches after the review pass | D676: Rentpost | E676: https://rentpost.com/resources/article/how-to-fix-a-sticky-lock | F676: landlord guide to fixing a sticky lock (search snippet)
A677: Fix a door lock that sticks or will not turn | B677: K | C677: =IFERROR(INDEX('Method & Notes'!$B$24:$B$34,MATCH(B677,'Method & Notes'!$A$24:$A$34,0)),"") -> Stakeholder input (Fast Fix Slack thread) | D677: Mark Bartholome, Fast Fix Slack thread (internal) | F677: named "door lock issue" as an example Fast Fix job
A678: Diagnose an appliance that is not working | B678: J | C678: =IFERROR(INDEX('Method & Notes'!$B$24:$B$34,MATCH(B678,'Method & Notes'!$A$24:$A$34,0)),"") -> Extra web searches after the review pass | D678: This Old House home warranty survey (2026) | E678: https://www.thisoldhouse.com/home-finances/home-warranty-survey | F678: nearly 40% of recent warranty claims were appliance-related (search snippet; refrigerators most claimed per an aggregator)
A679: Diagnose an appliance that is not working | B679: J | C679: =IFERROR(INDEX('Method & Notes'!$B$24:$B$34,MATCH(B679,'Method & Notes'!$A$24:$A$34,0)),"") -> Extra web searches after the review pass | D679: Sunset on Thumbtack summer 2024 ranking | E679: https://sunset.com/home-garden/design/most-popular-home-projects-summer-2024 | F679: appliance repair or maintenance ranked right after handyman among top maintenance projects (search snippet)
A680: Diagnose an appliance that is not working | B680: K | C680: =IFERROR(INDEX('Method & Notes'!$B$24:$B$34,MATCH(B680,'Method & Notes'!$A$24:$A$34,0)),"") -> Stakeholder input (Fast Fix Slack thread) | D680: Mark Bartholome, Fast Fix Slack thread (internal) | F680: named "appliance diagnostic" as an example Fast Fix job

Sheet Referred Out
A1: Popular job (not a Fast Fix) | B1: Why it is referred to a Service Request | C1: Angles that listed it
A2: Paint a whole room (interior painting) | B2: Over 3 hours; prep, coats and dry time. Only touch-ups and a single door, accent wall or small area fit Fast Fix (the small-area version is now in the catalog). | C2: A, B, C, D, E
A3: Roof repair or replacement, including hail damage | B3: Licensed roofer and beyond a standard step ladder. | C3: A, C, D, E, F, H
A4: AC or heating repair, furnace or HVAC replacement | B4: Licensed HVAC trade, refrigerant and gas work. | C4: A, B, C, D, E, F
A5: Repair or replace a water heater | B5: Licensed plumber, gas or high-amp electrical work; usually over 3 hours. | C5: C, D, E, H
A6: Install new appliances needing gas or new plumbing (range, dryer, wall oven) | B6: Gas work or new hookups need licensed trades. | C6: A, F
A7: Appliance repair (refrigerator, washer, dryer, oven) | B7: Appliance-technician diagnosis and parts; rarely one visit; possible gas. | C7: B, C, D, E
A8: Clean gutters on a two-story home or any job needing an extension ladder | B8: Needs an extension ladder or roof-edge access. The single-story, step-ladder version is now in the catalog as 'Clean gutters and add downspout extensions (single-story reach)'. | C8: A, B, C, D, F
A9: Pressure wash a patio, walkway or driveway | B9: Equipment-heavy and usually over 3 hours. | C9: A, B, F
A10: Install flooring | B10: Over 3 hours for most rooms. | C10: A, D, E, F
A11: Install tile (floor, backsplash, shower) | B11: Over 3 hours and needs cure time. Replacing one to three tiles and small grout repairs stay in the catalog. | C11: A, B, D, F
A12: Build or repair a deck or fence | B12: Over 3 hours, structural or outdoor carpentry. A few deck boards, a gate latch or a few pickets stay in the catalog. | C12: A, B, D, F
... A49: Install a smart water shutoff valve | B49: Insurer discounts mostly reward automatic shutoff valves, which are plumbing installs and out of scope; battery leak sensors alone often earn no discount. Evidence is thin and indirect. | C49: H

Sheet Runners-up
A1: Just missed the top 100 | B1: Why it did not make it
A2: Fix a garage door opener sensor, keypad, remote or bottom seal | B2: Both critics call it popular and eligible (springs and cables excluded), but the merge JSON has no URL for it and no web access was available to source it. Source before adding.
A3: Install a bidet seat or attachment | B3: Time and cost are documented (about 30 to 60 minutes by a handyman, one retailer plus a cost guide) but no popularity data was found. Needs an outlet or GFCI nearby.
A4: Replace faucet, toilet or washer supply lines | B4: Both critics. Partly covered by 'Fix a leak under a sink' and 'Replace a faucet'; no standalone source.
A5: Replace a sink drain stopper or pop-up assembly | B5: Both critics; unsourced in this run.
A6: Move or rearrange heavy furniture inside the home | B6: Coverage critic: large marketplace category, but a labor service needing a weight-limit and liability policy; unsourced.
A7: Repair wobbly or broken furniture (chair, table, bed frame) | B7: Coverage critic, medium confidence; unsourced.
A8: Insulate exposed pipes and cover outdoor faucets before a freeze | B8: Coverage critic: seasonal and local (TX after Winter Storm Uri, CO freezes); unsourced.
A9: Install garage wall storage (shelves, hooks, bike or ladder racks) | B9: Both critics; unsourced. No overhead ceiling racks.
A10: Install or replace a mailbox or house numbers | B10: Coverage critic; unsourced. No new concrete-set post.
A11: Swap recessed can lights for LED retrofit trims | B11: Both critics; no new wiring, about 6 lights per visit; unsourced.
A12: Install plug-in under-cabinet or LED strip lighting | B12: Coverage critic; unsourced.
... A35: Install a wall-mounted stair handrail | B35: Dropped in the second pass: supported by one research angle only, and replaced by a job with more mentions from angles G, H and I.

Sheet Method & Notes
A1: Method and notes
A3: Scoring inputs (change these and the ranking recalculates)
A4: Points per independent research angle that lists the job (max 9 angles with evidence) | B4: 10 | C4: Assumption: breadth of independent corroboration matters most, so each research angle counts 10 and each extra citation 1.
A5: Points per supporting mention (each mention is one source citation in the Evidence sheet) | B5: 1
A6: Cap on mentions that count toward the score | B6: 8
A7: Tier A (Core) starts at this score | B7: 70
A8: Tier B (Common) starts at this score | B8: 40
A10: Score = angles x B4 + MIN(mentions, B6) x B5. Tier = Core (>= B7), Common (>= B8), otherwise Frequent.
A12: About this workbook
A13: Purpose | B13: The 100 most requested small home jobs, to be used as the Fast Fix catalog. Fast Fix = one visit of 1 to 3 hours, member has the part, like-for-like swaps and repairs, no gas, no new wiring, no moved water lines, nothing above a standard step ladder.
A14: What "popular" means here | B14: Ranking reflects how many independent research angles (and how many sources) list the job as commonly requested, booked, claimed, searched or maintained. It is NOT measured request volume: marketplaces and PreFix keep their real request data private. Treat rank as a well-evidenced starting point and replace it with PreFix's own request data once Fast Fix is live.
A15: Research date | B15: 2026-10-16 (web research; pages and rankings change)
A16: How the list was built | B16: Nine research angles were planned (A to I). 9 of them returned cited evidence (A, B, C, D, E, F, G, H, I). All nine angles returned evidence. A merge editor canonicalized names, removed duplicates and selected 100 Fast Fix-eligible jobs; critics reviewed coverage and eligibility; a finalizer applied fixes; a short extra search pass then added three jobs and extra evidence (angles J and K).
A17: Typical time | B17: Typical on-site minutes for the common case. Mostly editorial judgement by the merge and review passes. Used only to decide whether a request is more than a Fast Fix covers. Never shown to members.
A18: Evidence limits (read this) | B18: 663 of the 680 citations are web-search result snippets (the rest are stakeholder input). The research environment could not open the cited pages (outbound connections to those sites were blocked), so no page was read in full and no figure (percentage, price, ranking) has been checked against the page itself. Every row on the Evidence sheet carries its URL so it can be verified. Treat the ranking as a well-sourced starting point, not audited data.
A19: Other limits | B19: Many sources are marketing content from handyman software, insurers and booking companies. No public ranking of most-booked tasks exists for Angi, Thumbtack or TaskRabbit, so popularity is inferred from how many independent angles list a job. Sources are mostly US; Texas and Colorado were checked specifically. Angles J and K (extra searches and the Slack thread) add mentions but are not counted as research angles.
A22: Research angles
A23: Code | B23: Angle | C23: Status | D23: Candidates found | E23: Sources reviewed | F23: Limitations reported by the research agent
A24: A | B24: Marketplaces and booking platforms | C24: Returned evidence | D24: 54 | E24: 15 | F24: No page was opened. Every WebFetch call failed with a DNS error, and a curl test to Thumbtack was refused by the egress proxy (403, host not allowed). A request to check the proxy status was denied by the permission classifier, so I did not retry or look for a workaround. All evidence therefore comes from WebSearch result summaries, which is why every signal ends in "(snippet)". Those summaries paraphrase pages, mix figures from several pages, and sometimes did not tie a number to one URL. That applies to the Angi outlet and weatherstripping figures, and I flagged them in the notes. Some cited pages are dated: Thumbtack guides are mostly 2024, TaskRabbit's Handyman Services page was reported as about 6.5 years old, and Handy's $59/$79 pricing is from January 2024. Most important: no marketplace publishes a ranked, numeric list of its most-requested handyman jobs. I found no request counts, shares or search volumes for individual tasks. Porch has only 2014 data and HomeAdvisor only 2020-2022 category counts. Yelp and Nextdoor yielded nothing usable. Popularity is therefore inferred from three weaker signals: a dedicated cost guide or category page on a marketplace (TV mounting, furniture assembly, ceiling fan, light fixture, faucet, drywall, door repair, blinds and thermostat have these on at least two platforms), being named in a platform's own task list, and recurring across independent lists. The strongest corroborated jobs are TV mounting, furniture assembly, hanging pictures, mirrors and shelves, ceiling fan and light fixture swaps, faucet work, drywall patching and door repair. Single-source items (toilet seat, smoke detector, air filter, dryer vent, bulbs, Wi-Fi setup, towel bars, closet shelving, cabinet hardware) should rank lower or be cross-checked against other research lenses. The only data-backed local signal is Thumbtack's 2025 holiday-light ranking (Austin 1, Dallas 2, Houston 6, San Antonio 9; Denver was not in the top 10 in the summaries I saw). TaskRabbit, Thimble, Amenify, Ace and Getjobber content is vendor marketing, and Angi says some of its guides are partly automated. Typical-minutes values are TaskRabbit or Handy hints where noted, otherwise my own estimates. Prices are context only and were not used to rank."
A25: B | B25: Handyman business guides | C25: Returned evidence | D25: 45 | E25: 22 | F25: I could not open any web page. Every WebFetch call failed with a DNS error (getaddrinfo ENOTFOUND) on every host I tried: thimble.com, getjobber.com, amenify.com, bobvila.com, joist.com, housecallpro.com and handoff.ai. So all evidence comes from WebSearch result summaries, which are paraphrases and not verbatim quotes. Every signal ends with "(snippet)" for that reason. I also tried one Bash command to read the proxy status and it was denied by the permission classifier. I did not work around that. I made 27 tool calls, a few over the 25 budget, mostly extra searches to get job-level detail. There is no hard popularity data. I found no search volumes, booking counts or percentages. The only data-backed claim is that Thimble's 2026 list "draws on public search data and Thimble customer data". It gave no figures, and its order (drywall, gutters, fixture replacement, patching and painting, tile, interior painting, deck) is only a general indication. A later search said no precise Thimble volume ranking was visible. Explicit ranks seen: WorkWave #1 faucet leak and #4 light fixture; Amenify #1 furniture assembly; TaskRabbit #1 wall mounting, #2 furniture, #3 caulking; Handyman Connection (2020) first four reasons are fixtures, painting, appliance repair, gutters. Most sources are handyman-business SEO guides that copy each other, so agreement across them is weak proof of real demand. Several are one author's opinion: the Ace Handyman release (one franchisee), the Bob Vila quote (one contractor) and the Handyman Connection blog. Some are Canadian or Australian (Upcover, HomeStars, Poyst). TaskRabbit is a marketplace and outside my lens. I found no franchise booking data for Mr. Handyman, Handyman Connection or Ace Handyman. The Mr. Handyman honey-do page showed no job list. Handoff, Joist and the full Jobber and Bob Vila lists were seen only in part. Typical minutes are my own judgement. No source I saw gave durations. Many small jobs are shown at category level only, and a few entries rest on one weak source: heavy mirror, running toilet, cabinet knobs, storm door, microwave. Two of these (the Housecall Pro doorbell and microwave claims) appeared in one search summary and were not reconfirmed later. Common jobs I expected but did not see confirmed in these sources: toilet seat swap, smoke detector install or battery, weatherstripping, grab bars, towel bars and bathroom accessories, baseboard and trim, pet door, shower head swap. Re-run this lens once page fetching works, and read the full Thimble, Jobber, Amenify, Bob Vila and Housecall Pro lists first."
A26: C | B26: Warranty claims and inspections | C26: Returned evidence | D26: 42 | E26: 19 | F26: Every WebFetch call failed (DNS errors, and a direct request to nachi.org was refused by the egress proxy), so I opened no page. Every signal above comes from WebSearch result summaries and is marked '(snippet)'. I did not try to bypass the block. I ran about 26 searches and fetch attempts. The summaries did not always say which result page a statement came from. Where I tied a quote to one URL among several results (the Waypoint caulk quote, the Houston handrail/weather-stripping list, the American Standard figures on a video page, the Home Warranty Association list), the attribution is my best match and should be checked. The American Standard running-toilet (31%) and sink-unclogging (33%) figures appeared in one search and could not be reproduced in a second, so treat them as unconfirmed. Warranty claim data is thin: American Home Shield, Choice, Cinch and Frontdoor publish no claim-category frequencies. The only warranty evidence is secondhand lists (furnace, dishwasher, disposal, toilets, ceiling fans) and vague surveys, and warranty claims skew to big systems and appliances that are out of scope. The strongest small-job evidence is two Repair Pricer datasets (2018 and 2021). They come from a vendor, use different sample sizes and counting methods, and should not be combined. Inspection defect rates measure what inspectors find, not what homeowners book. The ranks I give come from sorting the published percentages, not from a full list I saw. No search volumes or booking counts were seen. The last 3 candidates (exhaust fan, window screen, re-grout) and several others have no or only category-level evidence from this lens and are included on judgement, so weight them accordingly. Typical minutes are my judgement, not sourced. Denver-specific data is nearly absent, and Austin, Dallas and San Antonio had none; only Houston had local items. The sources are mostly US consumer and trade press with no peer review.
A27: D | B27: DIY and how-to interest | C27: Returned evidence | D27: 63 | E27: 19 | F27: WebFetch failed on every host I tried (todayshomeowner.com, familyhandyman.com, hookagency.com, bobvila.com, homedepot.com, thisoldhouse.com, en.wikipedia.org), all with DNS 'getaddrinfo ENOTFOUND', and a Bash call to check the proxy was denied. I therefore opened no page. All evidence comes from WebSearch result summaries, and every signal is marked (snippet). I spent about 31 tool calls, over the budget, trying to compensate with more searches. Thin data. I found no US search-volume table for job-level queries. The only numeric job-level signals are the Today's Homeowner Google Trends study (10 terms only), the 2017 Google 'how to fix' ranking (doors, windows, toilets, washing machines, refrigerators), and one third-party Amazon weekly volume for TV mounts. Most evidence is editorial listicles from Family Handyman and Bob Vila, which are one publisher's opinions, often years old, and list position is not demand. Lowe's workshop topics reflect a business choice. Cross-listing across many guides is the best proxy I have for popularity (strongest: running toilet, leaky faucet, caulk, drywall patch, weatherstripping, drains, garbage disposal, light switch or outlet). Unverified or conflicting: the Roto-Rooter claim (faucet repair top in 11 states, running toilet 8, broken window 6) appeared in one search summary and could not be re-confirmed, so I flagged it. Item-to-page attribution within the merged Bob Vila, TOH and Lowe's summaries is approximate. Bias of the DIY lens: it favors cheap plumbing and caulk fixes people try themselves and under-represents jobs people tend to pay for. I found no evidence at all for furniture assembly, smart device installs (video doorbell, thermostat, smart lock), blinds, toilet seat swaps, cabinet hardware, baby-proofing, or sliding-door repair, so none are in the list. TV mounting, picture hanging, shelves and curtain rods have only weak or non-US evidence. Other families (hiring and booking data) should cover those. No data specific to Austin, Dallas, Houston, San Antonio or Denver. Minutes are my judgement unless noted. Items needing cure or dry time (drywall, grout, caulk, tile) may not finish in one visit.
A28: E | B28: Rental and property maintenance requests | C28: Returned evidence | D28: 43 | E28: 26 | F28: 1) WebFetch failed with DNS errors (getaddrinfo ENOTFOUND) on every host I tried (hemlane.com, tenantcloud.com, upkeep.com, biggerpockets.com, wikipedia.org). I read no page directly. Every signal comes from WebSearch result summaries, so every signal ends with (snippet). A command to inspect proxy status was blocked by the permission system and I did not work around it. 2) The summaries are not tied line by line to URLs. Where a claim came from several pages returned by one search, I cited the best-matching page. This affects RentRedi, Lula and the make-ready checklists most. 3) No dataset in this lens ranks individual jobs. The real counts come from only two companies, Hemlane (193k+ requests, about 185k categorized) and Bay Property Management Group (22,354 requests), and both are self-published vendor or manager data. All other numbers are category-level. Hemlane's own pages disagree slightly (top four = 70% vs 71%). Plumbing is #1 at 25.4% even after the 21.5% 'Other' bucket. So job-level ranking here is inference from category rank plus named examples. Oxmaint and Belong share figures are unsourced or inconsistent, and I did not use them as evidence. 4) I found no request-type data from AppFolio, Buildium, Yardi, Zillow Rental Manager, TurboTenant, Landlord Studio, RentRedi, Latchel or Property Meld. 5) Rental data skews toward what landlords must fix, such as HVAC, plumbing and appliances. It under-represents owner-side jobs like TV mounting, shelf hanging, furniture assembly, blinds and smart-device installs, so this lens should not be used to rank those. 6) Many forum and listicle signals are one author's opinion (Multifamily Insiders, MassLandlords, vendor blogs) and are flagged as such. Corroborated across 3 or more independent sources: smoke/CO detector, dripping faucet, clogged drain, clogged toilet, garbage disposal jam, light bulb, air filter, door repair and lock work. 7) Typical minutes are my judgement, anchored only by Hemlane's Rent Ready+ rule that handyperson jobs run under 4 hours labor and $150 materials. They are not from a source. 8) Local licensing for outlet, fixture and rekey swaps varies by state (TX and CO) and was not checked."
A29: F | B29: Memberships, concierge and retailer services | C29: Returned evidence | D29: 55 | E29: 20 | F29: WebFetch failed on every host I tried with a DNS error (ENOTFOUND), so no page was opened. All evidence comes from WebSearch result summaries, which are paraphrased, not verbatim. Every signal is marked (snippet). I did not diagnose the fetch failure: a read of the proxy README was denied by the permission classifier and I did not work around it. The search budget ran out after about 37 searches, and two final queries (Best Buy camera and light-switch installs; Rebuilding Together's 40-repair list) were refused. Thin demand data. None of these sources gives national task-level counts or ranks. Real popularity statements are few and old: Amazon 2016 (TV mounting, furniture assembly, treadmill assembly), Handy Thanksgiving weekend 2016, one Mr. Handyman franchise's top 3 (doors, drywall, honey-do), one Ace Handyman owner's list (deck, bathroom caulking, stair, fence), Bob Vila quoting one handyman (drywall, light electrical, light plumbing), a Thimble 2026 list seen only via a search summary, and NAHB remodeler percentages (grab bars). Retailer pages from Lowe's, Home Depot and Best Buy show what is sold, which is supply and not demand, and lean toward appliances, TV mounting and smart-home installs. Missing from this lens: HomeServe, Frontdoor and Hello Alfred gave no usable small-job lists, and the unlimited-handyman memberships mostly sell hours or visits. Common tasks such as unclogging a drain, replacing a showerhead or toilet seat, hanging towel bars, replacing smoke detector batteries or fixing screens got no evidence here and need other source families. Attribution risks: the treadmill claim may come from a different Retail Dive article than the one cited. The Bob Vila ranking could sit on either of two Bob Vila URLs. The North Jersey smoke-detector claim could sit on either of two nj211 pages. The Amazon 2016 ranking is reported second-hand through a local TV station. The NAHB 87% figure's year is unclear. Honey Homes jobs come from a third-party listing of its page. Handy's app page was about 227 days old and the Home Depot smart-home page is old. Treat the Mr. Handyman, Ace, Bob Vila and Thimble lists as single-author or single-franchise opinion, and Thimble, Jobber and similar content as SEO marketing. Time estimates are Best Buy's listed times where cited (doorbell 60, thermostat 55, lock 90, basic TV mount 35, full TV setup 90-120) and my own judgement elsewhere.
A30: G | B30: Time, cost and scope guides | C30: Returned evidence | D30: 39 | E30: 14 | F30: I used 19 WebSearch calls and no WebFetch or curl. Every signal comes from search summaries, not page text, so URLs are real but exact wording and some figures may differ on the page. Several statistics could not be tied to one URL and are not cited as signals: toilet replacement ($200-$800), smoke/CO alarm swap ($70-$150), dryer vent cleaning ($100-$250), over-the-range microwave ($200-$600+), handrail install ($350-$1,200), smart lock, holiday lights, baby-proofing. Of those, only the handrail range is repeated in a note, and only in this paragraph: it suggests the stair handrail job may exceed 3 hrs. I found nothing usable for toilet replacement, smoke or CO alarms, dryer vent, microwave, handrail, smart lock, holiday lights, baby-proofing, sliding patio door, window air conditioner, spigot, deck boards, interior door swap, painting or tile, so those jobs carry no new evidence from me. Time figures are thin: most cost guides state price, not hours. Where hours appear they are summary-level, and ceiling fan, garbage disposal, bathroom exhaust fan and flat-pack assembly show ranges that touch or exceed 3 hrs. No new-job nominations are returned: no unlisted job reached 2 citable mentions (weak singles: garbage disposal removal, HomeGuide only; attic or whole-house fans, HomeAdvisor and Angi only). Licensing is flagged only for electrical swaps (check TX/CO rules) and is not confirmed by any source I saw. Austin, Dallas, Houston, San Antonio and Denver pricing was mostly unavailable; only TaskRabbit Dallas/Fort Worth, Thumbtack Frisco and an Austin toilet guide were in-market.
A31: H | B31: Regional, seasonal and emerging demand | C31: Returned evidence | D31: 39 | E31: 25 | F31: WebSearch returned synthesized per-query summaries with links, not raw page snippets, and WebFetch was unavailable. A signal is therefore a paraphrase of what the summary said a page contained, and I could not open any page to confirm. I ran 20 searches, about 2 over the budget of 18. No demand ranking or volume figure for Austin, Dallas, Houston, San Antonio or Denver was found. A Thumbtack or Angi 2025-26 trend report on smart doorbells, locks or cameras was not found, so emerging-demand evidence is market-level (Parks, Freedonia) or indirect. Weak coverage: Denver (thin; hail, HOA rules and sprinkler issues were not covered, and the sprinkler query never ran); leak-sensor demand (insurer-driven, mostly about shutoff valves); handrails, baby gates, furniture anchoring, window screens, cameras and holiday lights (no usable attributed evidence). Time evidence is thin: only grab bars (20 to 60 min per bar) and a baby-proofing range (4 to 14 hours whole-home, low-quality mirror pages) had stated durations. No per-device install times were found for thermostats, doorbells or smart locks. Attribution caveats: where one summary cited several pages, I tied a claim to a URL only when the text or title pointed to it. Best-match attributions: TaskRabbit San Antonio page, the Housecall Pro Texas licensing page, the CBS Colorado spigot point, and the grabbars.com 30 to 60 minute figure. Claims I could not tie to a URL were left out of mentions: an Austin list (leaky faucets, drywall after weather, ceiling fans), a Colorado guide (sticking doors, cabinets, knobs), AC condensate-line flushing (single source), smart thermostat market growth, and gate and strap prices. Licensing flags from the results: a Plano handyman page says HVAC and electrical work need licensed specialists; Texas pages say Dallas requires registration for fencing work and Houston may require a permit for repairs in city limits; Colorado has no state handyman license. Those are as reported and not verified against the city or state sources.
A32: I | B32: Search demand | C32: Returned evidence | D32: 17 | E32: 15 | F32: I used about 18 WebSearch calls and found job-level evidence for only 17 of the 100 listed jobs, well short of the 30 target. I found no strong new job nominations: nothing reached two job-level mentions outside the current list. No Google Trends write-up or 'most searched handyman services' report with job-level rankings turned up. No US monthly volume surfaced for several jobs: 'tv mounting service', 'ceiling fan installation', 'drywall repair', door lock repair or rekey, faucet replacement, light fixture or outlet replacement, caulking and others. The keyword-table sources (MarketKeep, RankHero, SEOJuice) were cut off or showed only broad terms. WebSearch returned summaries rather than raw rows, so I could not open any page to see more rows. Many figures are how-to query volumes (informational intent, not people hiring someone). Several are UK data (IFA Magazine) or Amazon product-search proxies (ASINSIGHT, EcomCrew), and each is labeled that way in its signal. The BigRentz/Ahrefs figures are undated and reached me only through secondary coverage. Hook Agency's ranking is category-level, so I attached it to smart-home install jobs only as a weak category signal. The unclog-drain figures are for generic drain queries, not sink or shower. Some URL-to-figure matches depend on which result the search summary referred to. None of my sources gave job durations, so typical_minutes is null throughout. Every signal comes from a snippet or search summary only; I opened no pages (WebFetch unavailable)."
A33: J | B33: Extra web searches after the review pass | C33: Added after review | F33: A short set of extra web searches run by hand after the review pass (TaskRabbit, Thumbtack, warranty, garage door, lock results). Search snippets only.
A34: K | B34: Stakeholder input (Fast Fix Slack thread) | C34: Added after review | F34: Job names the stakeholders gave as examples (running toilet, clogged toilet, door lock issue, disposal issue, appliance diagnostic).
A36: Checks before launch (from the eligibility reviewer; not verified against sources, not legal advice)
A37: Licensing | B37: Like-for-like electrical and plumbing swaps (light fixtures, outlets, faucets, toilets, disposals, dishwashers) may count as licensed work in Texas and Colorado even though no wiring or pipe is moved. Get written legal sign-off for each state before launch.
A38: Lead paint | B38: Paid work that disturbs painted surfaces in homes built before 1978 can fall under the EPA lead-safe rule. Ask the build year at booking for paint, patch, trim and caulk jobs.
A39: Ladder height | B39: Several jobs (bulbs, fans, chandeliers, window work, exterior caulk, gutters) can exceed a standard step ladder. Ask ceiling height and number of stories at booking.
A40: Heavy lifts | B40: Toilets, dishwashers, over-the-range microwaves, big TVs and sliding doors need a second adult for lifting.
A41: Structural signs | B41: Wide or stair-step cracks, rotted framing and sagging stairs are referrals, not Fast Fix. Texas clay soils make recurring cracks common.
A42: Gas and high tension | B42: No gas appliance work. Garage door springs and cables are never Fast Fix.
A44: Editorial notes from the merge and review
A45: SECOND PASS (angles G, H and I rerun after the first pass ran out of search budget).
A46: Second research pass (angles G time/cost/scope, H regional/seasonal/emerging, I search demand) added 190 citations to existing jobs. Every URL was checked against what the research agents actually returned.
A47: Typical time for "Replace a garbage disposal" changed from 90 to 120 minutes. G typical_minutes 120, which is 30 above the listed 90. Sources disagree: HomeGuide bases labor on 2 hours, HomeAdvisor says about 1 hour, Fixr assumes 3 hours; 120 is the median of the three. Hardwired units may need an electrician.
...

Sheet Sources
A1: Angle | B1: Source | C1: URL | D1: Agent reported it usable? | E1: Note
A2: A | B2: TaskRabbit (cost guides, service pages, 2024 trend post, handyman blog) | C2: https://www.taskrabbit.com/cost-guides/general-handyman | D2: Yes | E2: Search results only; no page opened. Gave prices, time hints and service lists. No published request-volume ranking. A TV guide FAQ has a placeholder (snippet).
A3: A | B3: Thumbtack (cost guides, category pages, 2025 Most Festive Cities) | C3: https://www.thumbtack.com/p/handyman-prices | D3: Yes | E3: Search results only. Many dedicated cost guides, mostly 2024 or older. No ranked list of most-booked handyman jobs. Festive Cities is the only ranking, and it covers holiday lights only.
A4: A | B4: Angi (cost guides, handyman articles, State of Home Spending) | C4: https://www.angi.com/articles/what-are-common-handyman-prices.htm | D4: Yes | E4: Search results only. Many dedicated 2026 cost guides with city pages. No handyman request ranking. State of Home Spending data covers whole-home projects. Angi says some guides are partly automated.
A5: A | B5: Handy | C5: https://www.handy.com/services | D5: Yes | E5: Search results only. Dedicated TV mounting and hanging pictures and shelves pages. Bookings now run through the Handy app. Frontdoor was not confirmed.
A6: A | B6: Airtasker US | C6: https://www.airtasker.com/us/costs/handyman/handyman-prices/ | D6: Yes | E6: Search results only. Per-task price bands for hanging, assembly, TV and shelves. No ranking.
A7: A | B7: Bark US | C7: https://www.bark.com/en/us/handyman/ | D7: Yes | E7: Thin. Handyman listings mention TV mounting, lighting, fans, outlets, assembly. No ranking.
A8: A | B8: Thimble blog (most requested handyman services) | C8: https://www.thimble.com/blog/what-are-the-most-requested-handyman-services | D8: Yes | E8: Not a marketplace. Says it combines public search data with its own customer data. Method and numbers not shown, and the list leans to larger jobs.
A9: A | B9: Amenify (top handyman tasks blog) | C9: https://www.amenify.com/blog/top-handyman-tasks-for-homeowners-in-us | D9: Yes | E9: Not a marketplace. Only a search summary of its 'most requested' list; the full article was not read and no booking data was seen.
A10: A | B10: Ace Handyman Services via HelloNation / PR Newswire (2026) | C10: https://smb.oxfordeagle.com/article/Home-Repair-Expert-Bryan-Harmon-Explains-the-Most-Common-Handyman-Tasks-in-HelloNation/6a08955bd6b3ec3c381af7f9 | D10: Yes | E10: Franchise PR, one source's opinion, no data.
A11: A | B11: Getjobber, Upcover, InstaService, Joist, Handoff handyman lists | C11: https://getjobber.com/academy/handyman/handyman-services-list/ | D11: No | E11: Contractor-marketing listicles seen only in search summaries. Used only as weak extras.
A12: A | B12: HomeAdvisor cost guide (Wayback snapshots) | C12: https://webcf.waybackmachine.org/web/20220816230350/https://www.homeadvisor.com/cost | D12: No | E12: Only 2020-2022 archive snapshots surfaced. Handyman had 109,026 projects in Aug 2022 (snippet), but no per-task counts and no total, so no ranking.
... A46: C | B46: Choice Home Warranty (news and reviews) | C46: https://www.wtkr.com/money/consumer/dont-waste-your-money/popular-home-warranty-company-now-has-over-5k-complaints | D46: No | E46: Complaint stories only; reviews mention HVAC, plumbing and appliances. No claim breakdown.
A47: C | B47: Cinch Home Services | D47: No | E47: Searched in a combined query; nothing relevant surfaced.
A48: C | B48: This Old House home warranty survey (2026) | C48: https://www.thisoldhouse.com/home-finances/home-warranty-survey | D48: No | E48: Only a category mix, relayed secondhand (about 49% systems, about 40% appliances). No small-job detail.
